Workbook

Sheet Stats
C1: Date | I1: 43008 | M1: 43015 | Q1: 43022 | U1: 43029 | Y1: 43036 | AC1: 43050 | AG1: 43057 | AK1: 43064 | AO1: 43071 | AS1: 43078 | AW1: 43113 | BA1: 43120 | BE1: 43127 | BI1: 43141 | BM1: 43148 | BQ1: 43155 | BU1: 43162 | BY1: 43176 | CC1: 43183 | CG1: 43204
C2: Team | I2: Hillcroft B | M2: Welwyn 2 | Q2: Spencer 3 | U2: Epsom | Y2: Maidstone | AC2: Hillcroft A | AG2: EG | AK2: Oxford Uni | AO2: Hillcroft A | AS2: Spencer 2 | AW2: Hillcroft B | BA2: Welwyn 2 | BE2: Spencer 3 | BI2: Epsom | BM2: Maidstone | BQ2: Hillcroft A | BU2: EG | BY2: Spencer 2 | CC2: Oxford Uni | CG2: EG
C3: Venue | H3: Avg | I3: Away | M3: Home | Q3: Away | U3: Home | Y3: Away | AC3: Away | AG3: Away | AK3: Away | AO3: Home | AS3: Home | AW3: Home | BA3: Away | BE3: Home | BI3: Away | BM3: Home | BQ3: Away | BU3: Home | BY3: Away | CC3: Home | CG3: Home
C4: Competition | I4: East1 | M4: East1 | Q4: East1 | U4: East1 | Y4: East1 | AC4: Int Flags | AG4: East1 | AK4: East1 | AO4: East1 | AS4: East1 | AW4: East1 | BA4: East1 | BE4: East1 | BI4: East1 | BM4: East1 | BQ4: East1 | BU4: East1 | BY4: East1 | CC4: East1 | CG4: East1
C5: For | G5: =SUM(I5:CG5) -> 108 | H5: =IF(G7=0,"",G5/G7) -> 6.3529412 | I5: =SUM(J10:J49) -> 6 | M5: =SUM(N10:N49) -> 15 | Q5: =SUM(R10:R49) -> 3 | U5: =SUM(V10:V49) -> 10 | Y5: =SUM(Z10:Z49) -> 6 | AC5: =SUM(AD10:AD49) -> 3 | AG5: P-P | AK5: =SUM(AL10:AL49) -> 5 | AO5: =SUM(AP10:AP49) -> 8 | AS5: =SUM(AT10:AT49) -> 3 | AW5: =SUM(AX10:AX49) -> 8 | BA5: =SUM(BB10:BB49) -> 7 | BE5: =SUM(BF10:BF49) -> 8 | BI5: =SUM(BJ10:BJ49) -> 7 | BM5: 10 | BQ5: =SUM(BR10:BR49) -> 2 | BU5: P-P | BY5: Abandoned | CC5: =SUM(CD10:CD49) -> 4 | CG5: =SUM(CH10:CH49) -> 3
C6: Against | G6: =SUM(I6:CG6) -> 143 | H6: =IF(G7=0,"",G6/G7) -> 8.4117647 | I6: 4 | M6: 2 | Q6: 10 | U6: 6 | Y6: 6 | AC6: 18 | AK6: 11 | AO6: 14 | AS6: 10 | AW6: 8 | BA6: 5 | BE6: 8 | BI6: 5 | BM6: 0 | BQ6: 11 | CC6: 16 | CG6: 9
C7: Played | G7: =COUNT(I6:CG6) -> 17
A8: Columns: Position (GDMA), Goals, Assists, Referee-quarters
A9: No. | B9: Name | C9: Sutname | E9: Position | F9: Apps | G9: Goals | H9: Assts | I9: P | J9: G | K9: A | L9: R | M9: P | N9: G | O9: A | P9: R | Q9: P | R9: G | S9: A | T9: R | U9: P | V9: G | W9: A | X9: R | Y9: P | Z9: G | AA9: A | AB9: R | AC9: P | AD9: G | AE9: A | AF9: R | AG9: P | AH9: G | AI9: A | AJ9: R | AK9: P | AL9: G | AM9: A | AN9: R | AO9: P | AP9: G | AQ9: A | AR9: R | AS9: P | AT9: G | AU9: A | AV9: R | AW9: P | AX9: G | AY9: A | AZ9: R | BA9: P | BB9: G | BC9: A | BD9: R | BE9: P | BF9: G | BG9: A | BH9: R | BI9: P | BJ9: G | BK9: A | BL9: R | BM9: P | BN9: G | BO9: A | BP9: R | BQ9: P | BR9: G | BS9: A | BT9: R | BU9: P | BV9: G | BW9: A | BX9: R | BY9: P | BZ9: G | CA9: A | CB9: R | CC9: P | CD9: G | CE9: A | CF9: R | CG9: P | CH9: G | CI9: A | CJ9: R
A10: 888 | B10: Jordan | C10: Anning | D10: =IF(C10<>"",CONCATENATE(B10," ",C10),B10) -> Jordan Anning | E10: Midfield | F10: =COUNTIF(I10:CO10,"=*") -> 1 | G10: =SUMIF(I$9:CO$9,"G",I10:CO10) -> 0 | H10: =SUMIF(I$9:CO$9,"A",I10:CO10) -> 0 | AW10: M
A11: 888 | B11: Lorenzo | C11: Balzarini | D11: =IF(C11<>"",CONCATENATE(B11," ",C11),B11) -> Lorenzo Balzarini | E11: Midfield | F11: =COUNTIF(I11:CO11,"=*") -> 10 | G11: =SUMIF(I$9:CO$9,"G",I11:CO11) -> 7 | H11: =SUMIF(I$9:CO$9,"A",I11:CO11) -> 0 | Y11: M | Z11: 2 | AC11: M | AD11: 1 | AK11: M | AO11: M | AS11: M | AW11: M | AX11: 2 | BE11: M | BF11: 1 | BI11: M | BJ11: 1 | BQ11: M | CG11: M
A12: 5 | B12: Justin | C12: Baranowski | D12: =IF(C12<>"",CONCATENATE(B12," ",C12),B12) -> Justin Baranowski | E12: Attack | F12: =COUNTIF(I12:CO12,"=*") -> 13 | G12: =SUMIF(I$9:CO$9,"G",I12:CO12) -> 14 | H12: =SUMIF(I$9:CO$9,"A",I12:CO12) -> 0 | I12: A | J12: 2 | M12: A | N12: 2 | Q12: A | U12: A | V12: 1 | Y12: A | Z12: 1 | AC12: A | AD12: 1 | AK12: A | AL12: 2 | AO12: A | AP12: 1 | AS12: A | BE12: A | BF12: 2 | BI12: A | BQ12: A | CC12: A | CD12: 2
A13: 888 | B13: Sam | C13: Baranowski | D13: =IF(C13<>"",CONCATENATE(B13," ",C13),B13) -> Sam Baranowski | E13: Midfield | F13: =COUNTIF(I13:CO13,"=*") -> 10 | G13: =SUMIF(I$9:CO$9,"G",I13:CO13) -> 0 | H13: =SUMIF(I$9:CO$9,"A",I13:CO13) -> 0 | I13: M | M13: M | Q13: M | U13: M | AC13: M | AK13: M | AO13: M | BQ13: M | CC13: M | CG13: M
A14: 888 | B14: Mike | C14: Barratt | D14: =IF(C14<>"",CONCATENATE(B14," ",C14),B14) -> Mike Barratt | E14: Midfield/FO | F14: =COUNTIF(I14:CO14,"=*") -> 6 | G14: =SUMIF(I$9:CO$9,"G",I14:CO14) -> 8 | H14: =SUMIF(I$9:CO$9,"A",I14:CO14) -> 0 | M14: M | N14: 2 | AO14: M | AP14: 1 | AS14: M | AT14: 1 | BE14: M | BF14: 3 | CC14: M | CG14: M | CH14: 1
A15: 888 | B15: Dave | C15: Berman | D15: =IF(C15<>"",CONCATENATE(B15," ",C15),B15) -> Dave Berman | E15: Midfield | F15: =COUNTIF(I15:CO15,"=*") -> 3 | G15: =SUMIF(I$9:CO$9,"G",I15:CO15) -> 4 | H15: =SUMIF(I$9:CO$9,"A",I15:CO15) -> 0 | I15: M | J15: 2 | M15: M | N15: 1 | CG15: A | CH15: 1
A16: 888 | B16: Lewis | C16: Blackshaw | D16: =IF(C16<>"",CONCATENATE(B16," ",C16),B16) -> Lewis Blackshaw | E16: Midfield | F16: =COUNTIF(I16:CO16,"=*") -> 1 | G16: =SUMIF(I$9:CO$9,"G",I16:CO16) -> 0 | H16: =SUMIF(I$9:CO$9,"A",I16:CO16) -> 0 | AS16: M
A17: 3 | B17: Andy | C17: Booth | D17: =IF(C17<>"",CONCATENATE(B17," ",C17),B17) -> Andy Booth | E17: Defence | F17: =COUNTIF(I17:CO17,"=*") -> 12 | G17: =SUMIF(I$9:CO$9,"G",I17:CO17) -> 0 | H17: =SUMIF(I$9:CO$9,"A",I17:CO17) -> 0 | I17: D | M17: D | Q17: D | U17: D | Y17: D | AK17: M | AO17: D | AS17: D | AZ17: 4 | BA17: D | BE17: D | BI17: D | BQ17: D | CF17: 4 | CJ17: 4
A18: 888 | B18: Lygon | C18: Bowen-west | D18: =IF(C18<>"",CONCATENATE(B18," ",C18),B18) -> Lygon Bowen-west | E18: Goal | F18: =COUNTIF(I18:CO18,"=*") -> 1 | G18: =SUMIF(I$9:CO$9,"G",I18:CO18) -> 0 | H18: =SUMIF(I$9:CO$9,"A",I18:CO18) -> 0 | U18: G
A19: 888 | B19: Billy | C19: Camuso | D19: =IF(C19<>"",CONCATENATE(B19," ",C19),B19) -> Billy Camuso | E19: Attack | F19: =COUNTIF(I19:CO19,"=*") -> 9 | G19: =SUMIF(I$9:CO$9,"G",I19:CO19) -> 2 | H19: =SUMIF(I$9:CO$9,"A",I19:CO19) -> 0 | I19: A | M19: A | Q19: A | Y19: A | AC19: A | AK19: A | BI19: A | BJ19: 1 | BQ19: A | BR19: 1 | CG19: A
A20: 6 | B20: David | C20: Copple | D20: =IF(C20<>"",CONCATENATE(B20," ",C20),B20) -> David Copple | E20: Defence | F20: =COUNTIF(I20:CO20,"=*") -> 14 | G20: =SUMIF(I$9:CO$9,"G",I20:CO20) -> 0 | H20: =SUMIF(I$9:CO$9,"A",I20:CO20) -> 0 | I20: D | M20: D | Q20: D | U20: D | AC20: D | AO20: D | AS20: D | AW20: D | BA20: D | BE20: D | BI20: D | BQ20: D | CC20: D | CG20: D
A21: 888 | B21: Eddie | C21: Dale | D21: =IF(C21<>"",CONCATENATE(B21," ",C21),B21) -> Eddie Dale | E21: Midfield/FO | F21: =COUNTIF(I21:CO21,"=*") -> 6 | G21: =SUMIF(I$9:CO$9,"G",I21:CO21) -> 0 | H21: =SUMIF(I$9:CO$9,"A",I21:CO21) -> 0 | I21: M | M21: M | Q21: M | U21: M | Y21: M | AC21: M
A22: 888 | B22: Will | C22: Duval | D22: =IF(C22<>"",CONCATENATE(B22," ",C22),B22) -> Will Duval | E22: Midfield | F22: =COUNTIF(I22:CO22,"=*") -> 1 | G22: =SUMIF(I$9:CO$9,"G",I22:CO22) -> 1 | H22: =SUMIF(I$9:CO$9,"A",I22:CO22) -> 0 | Q22: M | R22: 1
A23: 888 | B23: Eugene | C23: Fung | D23: =IF(C23<>"",CONCATENATE(B23," ",C23),B23) -> Eugene Fung | E23: Midfield | F23: =COUNTIF(I23:CO23,"=*") -> 1 | G23: =SUMIF(I$9:CO$9,"G",I23:CO23) -> 0 | H23: =SUMIF(I$9:CO$9,"A",I23:CO23) -> 0 | Q23: M
A24: 888 | B24: Sam | C24: Guest | D24: =IF(C24<>"",CONCATENATE(B24," ",C24),B24) -> Sam Guest | E24: Defence | F24: =COUNTIF(I24:CO24,"=*") -> 3 | G24: =SUMIF(I$9:CO$9,"G",I24:CO24) -> 1 | H24: =SUMIF(I$9:CO$9,"A",I24:CO24) -> 0 | AW24: D | AX24: 1 | BE24: D | CG24: D
A25: 888 | B25: Jacob | C25: Hall | D25: =IF(C25<>"",CONCATENATE(B25," ",C25),B25) -> Jacob Hall | E25: Midfield | F25: =COUNTIF(I25:CO25,"=*") -> 5 | G25: =SUMIF(I$9:CO$9,"G",I25:CO25) -> 1 | H25: =SUMIF(I$9:CO$9,"A",I25:CO25) -> 0 | Y25: M | Z25: 1 | AK25: M | AW25: M | BA25: M | BE25: M
A26: 888 | B26: Sam | C26: Hallows | D26: =IF(C26<>"",CONCATENATE(B26," ",C26),B26) -> Sam Hallows | E26: Attack | F26: =COUNTIF(I26:CO26,"=*") -> 3 | G26: =SUMIF(I$9:CO$9,"G",I26:CO26) -> 0 | H26: =SUMIF(I$9:CO$9,"A",I26:CO26) -> 0 | BQ26: A | CC26: A | CG26: A
A27: 888 | B27: David | C27: Hudson | D27: =IF(C27<>"",CONCATENATE(B27," ",C27),B27) -> David Hudson | E27: Defence | F27: =COUNTIF(I27:CO27,"=*") -> 1 | G27: =SUMIF(I$9:CO$9,"G",I27:CO27) -> 0 | H27: =SUMIF(I$9:CO$9,"A",I27:CO27) -> 0 | CG27: M
A28: 888 | B28: Ben | C28: Iremonger | D28: =IF(C28<>"",CONCATENATE(B28," ",C28),B28) -> Ben Iremonger | E28: Midfield | F28: =COUNTIF(I28:CO28,"=*") -> 7 | G28: =SUMIF(I$9:CO$9,"G",I28:CO28) -> 8 | H28: =SUMIF(I$9:CO$9,"A",I28:CO28) -> 0 | M28: M | N28: 2 | Q28: M | U28: M | V28: 1 | Y28: M | AS28: M | BA28: M | BB28: 4 | BE28: M | BF28: 1
A29: 888 | B29: Luke | C29: Johnstone | D29: =IF(C29<>"",CONCATENATE(B29," ",C29),B29) -> Luke Johnstone | E29: Attack | F29: =COUNTIF(I29:CO29,"=*") -> 3 | G29: =SUMIF(I$9:CO$9,"G",I29:CO29) -> 3 | H29: =SUMIF(I$9:CO$9,"A",I29:CO29) -> 0 | I29: A | J29: 1 | U29: A | V29: 2 | CG29: A
A30: 9 | B30: Myles | C30: Johnstone | D30: =IF(C30<>"",CONCATENATE(B30," ",C30),B30) -> Myles Johnstone | E30: Midfield | F30: =COUNTIF(I30:CO30,"=*") -> 15 | G30: =SUMIF(I$9:CO$9,"G",I30:CO30) -> 7 | H30: =SUMIF(I$9:CO$9,"A",I30:CO30) -> 0 | I30: M | J30: 1 | M30: M | Q30: M | U30: M | V30: 1 | Y30: M | Z30: 1 | AC30: M | AK30: M | AL30: 1 | AO30: A | AS30: A | AW30: A | BA30: A | BB30: 1 | BE30: A | BF30: 1 | BI30: A | CC30: M | CG30: M | CH30: 1
A31: 888 | B31: Will | C31: Lucas | D31: =IF(C31<>"",CONCATENATE(B31," ",C31),B31) -> Will Lucas | E31: Defence | F31: =COUNTIF(I31:CO31,"=*") -> 3 | G31: =SUMIF(I$9:CO$9,"G",I31:CO31) -> 0 | H31: =SUMIF(I$9:CO$9,"A",I31:CO31) -> 0 | AK31: D | CC31: D | CG31: D
A32: 888 | B32: Kieran | C32: Kershaw | D32: =IF(C32<>"",CONCATENATE(B32," ",C32),B32) -> Kieran Kershaw | E32: Midfield | F32: =COUNTIF(I32:CO32,"=*") -> 1 | G32: =SUMIF(I$9:CO$9,"G",I32:CO32) -> 0 | H32: =SUMIF(I$9:CO$9,"A",I32:CO32) -> 0 | BQ32: M
A33: 888 | B33: Charlie | C33: Merry | D33: =IF(C33<>"",CONCATENATE(B33," ",C33),B33) -> Charlie Merry | E33: Defence | F33: =COUNTIF(I33:CO33,"=*") -> 1 | G33: =SUMIF(I$9:CO$9,"G",I33:CO33) -> 0 | H33: =SUMIF(I$9:CO$9,"A",I33:CO33) -> 0 | U33: D
A34: 888 | B34: Conor | C34: Mills | D34: =IF(C34<>"",CONCATENATE(B34," ",C34),B34) -> Conor Mills | E34: Defence | F34: =COUNTIF(I34:CO34,"=*") -> 7 | G34: =SUMIF(I$9:CO$9,"G",I34:CO34) -> 0 | H34: =SUMIF(I$9:CO$9,"A",I34:CO34) -> 0 | Y34: D | AK34: D | AO34: D | BA34: D | BQ34: D | CC34: D | CG34: D
A35: 7 | B35: Matt | C35: Payne | D35: =IF(C35<>"",CONCATENATE(B35," ",C35),B35) -> Matt Payne | E35: Attack | F35: =COUNTIF(I35:CO35,"=*") -> 12 | G35: =SUMIF(I$9:CO$9,"G",I35:CO35) -> 23 | H35: =SUMIF(I$9:CO$9,"A",I35:CO35) -> 0 | M35: A | N35: 5 | Q35: A | R35: 1 | U35: A | V35: 3 | AC35: A | AD35: 1 | AK35: A | AL35: 2 | AO35: A | AP35: 5 | AS35: A | AT35: 1 | AW35: A | AX35: 2 | BE35: A | BI35: A | BJ35: 2 | CC35: A | CD35: 1 | CG35: A
A36: 888 | B36: Richard | C36: Pearse | D36: =IF(C36<>"",CONCATENATE(B36," ",C36),B36) -> Richard Pearse | E36: Midfield | F36: =COUNTIF(I36:CO36,"=*") -> 12 | G36: =SUMIF(I$9:CO$9,"G",I36:CO36) -> 8 | H36: =SUMIF(I$9:CO$9,"A",I36:CO36) -> 0 | I36: M | M36: M | N36: 2 | Y36: A | AC36: M | AO36: M | AS36: M | AT36: 1 | AW36: M | BA36: A | BB36: 1 | BI36: M | BJ36: 3 | BQ36: M | BR36: 1 | CC36: M | CG36: M
A37: 888 | B37: Eliot | C37: Pugh | D37: =IF(C37<>"",CONCATENATE(B37," ",C37),B37) -> Eliot Pugh | E37: Goal | F37: =COUNTIF(I37:CO37,"=*") -> 1 | G37: =SUMIF(I$9:CO$9,"G",I37:CO37) -> 0 | H37: =SUMIF(I$9:CO$9,"A",I37:CO37) -> 0 | AS37: G
A38: 888 | B38: Ben | C38: Reed | D38: =IF(C38<>"",CONCATENATE(B38," ",C38),B38) -> Ben Reed | E38: Attack | F38: =COUNTIF(I38:CO38,"=*") -> 1 | G38: =SUMIF(I$9:CO$9,"G",I38:CO38) -> 3 | H38: =SUMIF(I$9:CO$9,"A",I38:CO38) -> 0 | AW38: A | AX38: 3
A39: 28 | B39: Dave | C39: Slaughter | D39: =IF(C39<>"",CONCATENATE(B39," ",C39),B39) -> Dave Slaughter | E39: Defence | F39: =COUNTIF(I39:CO39,"=*") -> 9 | G39: =SUMIF(I$9:CO$9,"G",I39:CO39) -> 1 | H39: =SUMIF(I$9:CO$9,"A",I39:CO39) -> 0 | I39: D | P39: 4 | Q39: G | X39: 4 | Y39: D | AC39: D | AK39: D | AR39: 4 | AV39: 4 | AW39: G | BA39: A | BB39: 1 | BH39: 4 | BI39: D | BQ39: D
A40: 888 | B40: Jacob | C40: Thorne | D40: =IF(C40<>"",CONCATENATE(B40," ",C40),B40) -> Jacob Thorne | E40: Goal | F40: =COUNTIF(I40:CO40,"=*") -> 12 | G40: =SUMIF(I$9:CO$9,"G",I40:CO40) -> 0 | H40: =SUMIF(I$9:CO$9,"A",I40:CO40) -> 0 | I40: G | M40: G | Y40: G | AC40: G | AK40: G | AO40: G | BA40: G | BE40: G | BI40: G | BQ40: G | CC40: G | CG40: G
...

Sheet Summary
G1: East1 | J1: Int Flags | M1: Friendly
G2: League | H2: League | I2: League | J2: Flags | K2: Flags | L2: Flags | M2: Friendly | N2: Friendly | O2: Friendly | P2: Referee | Q2: Referee
A3: No. | B3: Name | C3: Position | D3: Apps | E3: Goals | F3: Avg | G3: Apps | H3: Goals | I3: Avg | J3: Apps | K3: Goals | L3: Avg | M3: Apps | N3: Goals | O3: Avg | P3: Games | Q3: Quarters
A5: =Stats!A10 -> 888 | B5: =Stats!D10 -> Jordan Anning | C5: =Stats!E10 -> Midfield | D5: =SUM(G5,J5,M5) -> 1 | E5: =SUM(H5,K5,N5) -> 0 | F5: =IF(D5>0,E5/D5,"") -> 0 | G5: =COUNTIFS(Stats!$I$4:$CG$4,G$1,Stats!$I10:$CG10,"<>") -> 1 | H5: =SUMIF(Stats!$I$4:$CF$4,G$1,Stats!$J10:$CI10) -> 0 | I5: =IF(G5>0,H5/G5,"") -> 0 | J5: =COUNTIFS(Stats!$I$4:$CG$4,J$1,Stats!$I10:$CG10,"<>") -> 0 | K5: =SUMIF(Stats!$I$4:$CF$4,J$1,Stats!$J10:$CI10) -> 0 | L5: =IF(J5>0,K5/J5,"") | M5: =COUNTIFS(Stats!$I$4:$CG$4,M$1,Stats!$I10:$CG10,"<>") -> 0 | N5: =SUMIF(Stats!$I$4:$CF$4,M$1,Stats!$J10:$CI10) -> 0 | O5: =IF(M5>0,N5/M5,"") | P5: =COUNTIFS(Stats!$L$9:$CG$9,"R",Stats!$L10:$CG10,">0") -> 0 | Q5: =SUMIF(Stats!$L$9:$CG$9,"R",Stats!$L10:$CG10) -> 0 | R5: =Stats!G10-E5 -> 0
A6: =Stats!A11 -> 888 | B6: =Stats!D11 -> Lorenzo Balzarini | C6: =Stats!E11 -> Midfield | D6: =SUM(G6,J6,M6) -> 10 | E6: =SUM(H6,K6,N6) -> 7 | F6: =IF(D6>0,E6/D6,"") -> 0.7 | G6: =COUNTIFS(Stats!$I$4:$CG$4,G$1,Stats!$I11:$CG11,"<>") -> 9 | H6: =SUMIF(Stats!$I$4:$CF$4,G$1,Stats!$J11:$CI11) -> 6 | I6: =IF(G6>0,H6/G6,"") -> 0.66666667 | J6: =COUNTIFS(Stats!$I$4:$CG$4,J$1,Stats!$I11:$CG11,"<>") -> 1 | K6: =SUMIF(Stats!$I$4:$CF$4,J$1,Stats!$J11:$CI11) -> 1 | L6: =IF(J6>0,K6/J6,"") -> 1 | M6: =COUNTIFS(Stats!$I$4:$CG$4,M$1,Stats!$I11:$CG11,"<>") -> 0 | N6: =SUMIF(Stats!$I$4:$CF$4,M$1,Stats!$J11:$CI11) -> 0 | O6: =IF(M6>0,N6/M6,"") | P6: =COUNTIFS(Stats!$L$9:$CG$9,"R",Stats!$L11:$CG11,">0") -> 0 | Q6: =SUMIF(Stats!$L$9:$CG$9,"R",Stats!$L11:$CG11) -> 0 | R6: =Stats!G11-E6 -> 0
A7: =Stats!A12 -> 5 | B7: =Stats!D12 -> Justin Baranowski | C7: =Stats!E12 -> Attack | D7: =SUM(G7,J7,M7) -> 13 | E7: =SUM(H7,K7,N7) -> 14 | F7: =IF(D7>0,E7/D7,"") -> 1.0769231 | G7: =COUNTIFS(Stats!$I$4:$CG$4,G$1,Stats!$I12:$CG12,"<>") -> 12 | H7: =SUMIF(Stats!$I$4:$CF$4,G$1,Stats!$J12:$CI12) -> 13 | I7: =IF(G7>0,H7/G7,"") -> 1.0833333 | J7: =COUNTIFS(Stats!$I$4:$CG$4,J$1,Stats!$I12:$CG12,"<>") -> 1 | K7: =SUMIF(Stats!$I$4:$CF$4,J$1,Stats!$J12:$CI12) -> 1 | L7: =IF(J7>0,K7/J7,"") -> 1 | M7: =COUNTIFS(Stats!$I$4:$CG$4,M$1,Stats!$I12:$CG12,"<>") -> 0 | N7: =SUMIF(Stats!$I$4:$CF$4,M$1,Stats!$J12:$CI12) -> 0 | O7: =IF(M7>0,N7/M7,"") | P7: =COUNTIFS(Stats!$L$9:$CG$9,"R",Stats!$L12:$CG12,">0") -> 0 | Q7: =SUMIF(Stats!$L$9:$CG$9,"R",Stats!$L12:$CG12) -> 0 | R7: =Stats!G12-E7 -> 0
A8: =Stats!A13 -> 888 | B8: =Stats!D13 -> Sam Baranowski | C8: =Stats!E13 -> Midfield | D8: =SUM(G8,J8,M8) -> 10 | E8: =SUM(H8,K8,N8) -> 0 | F8: =IF(D8>0,E8/D8,"") -> 0 | G8: =COUNTIFS(Stats!$I$4:$CG$4,G$1,Stats!$I13:$CG13,"<>") -> 9 | H8: =SUMIF(Stats!$I$4:$CF$4,G$1,Stats!$J13:$CI13) -> 0 | I8: =IF(G8>0,H8/G8,"") -> 0 | J8: =COUNTIFS(Stats!$I$4:$CG$4,J$1,Stats!$I13:$CG13,"<>") -> 1 | K8: =SUMIF(Stats!$I$4:$CF$4,J$1,Stats!$J13:$CI13) -> 0 | L8: =IF(J8>0,K8/J8,"") -> 0 | M8: =COUNTIFS(Stats!$I$4:$CG$4,M$1,Stats!$I13:$CG13,"<>") -> 0 | N8: =SUMIF(Stats!$I$4:$CF$4,M$1,Stats!$J13:$CI13) -> 0 | O8: =IF(M8>0,N8/M8,"") | P8: =COUNTIFS(Stats!$L$9:$CG$9,"R",Stats!$L13:$CG13,">0") -> 0 | Q8: =SUMIF(Stats!$L$9:$CG$9,"R",Stats!$L13:$CG13) -> 0 | R8: =Stats!G13-E8 -> 0
A9: =Stats!A14 -> 888 | B9: =Stats!D14 -> Mike Barratt | C9: =Stats!E14 -> Midfield/FO | D9: =SUM(G9,J9,M9) -> 6 | E9: =SUM(H9,K9,N9) -> 7 | F9: =IF(D9>0,E9/D9,"") -> 1.1666667 | G9: =COUNTIFS(Stats!$I$4:$CG$4,G$1,Stats!$I14:$CG14,"<>") -> 6 | H9: =SUMIF(Stats!$I$4:$CF$4,G$1,Stats!$J14:$CI14) -> 7 | I9: =IF(G9>0,H9/G9,"") -> 1.1666667 | J9: =COUNTIFS(Stats!$I$4:$CG$4,J$1,Stats!$I14:$CG14,"<>") -> 0 | K9: =SUMIF(Stats!$I$4:$CF$4,J$1,Stats!$J14:$CI14) -> 0 | L9: =IF(J9>0,K9/J9,"") | M9: =COUNTIFS(Stats!$I$4:$CG$4,M$1,Stats!$I14:$CG14,"<>") -> 0 | N9: =SUMIF(Stats!$I$4:$CF$4,M$1,Stats!$J14:$CI14) -> 0 | O9: =IF(M9>0,N9/M9,"") | P9: =COUNTIFS(Stats!$L$9:$CG$9,"R",Stats!$L14:$CG14,">0") -> 0 | Q9: =SUMIF(Stats!$L$9:$CG$9,"R",Stats!$L14:$CG14) -> 0 | R9: =Stats!G14-E9 -> 1
A10: =Stats!A15 -> 888 | B10: =Stats!D15 -> Dave Berman | C10: =Stats!E15 -> Midfield | D10: =SUM(G10,J10,M10) -> 3 | E10: =SUM(H10,K10,N10) -> 3 | F10: =IF(D10>0,E10/D10,"") -> 1 | G10: =COUNTIFS(Stats!$I$4:$CG$4,G$1,Stats!$I15:$CG15,"<>") -> 3 | H10: =SUMIF(Stats!$I$4:$CF$4,G$1,Stats!$J15:$CI15) -> 3 | I10: =IF(G10>0,H10/G10,"") -> 1 | J10: =COUNTIFS(Stats!$I$4:$CG$4,J$1,Stats!$I15:$CG15,"<>") -> 0 | K10: =SUMIF(Stats!$I$4:$CF$4,J$1,Stats!$J15:$CI15) -> 0 | L10: =IF(J10>0,K10/J10,"") | M10: =COUNTIFS(Stats!$I$4:$CG$4,M$1,Stats!$I15:$CG15,"<>") -> 0 | N10: =SUMIF(Stats!$I$4:$CF$4,M$1,Stats!$J15:$CI15) -> 0 | O10: =IF(M10>0,N10/M10,"") | P10: =COUNTIFS(Stats!$L$9:$CG$9,"R",Stats!$L15:$CG15,">0") -> 0 | Q10: =SUMIF(Stats!$L$9:$CG$9,"R",Stats!$L15:$CG15) -> 0 | R10: =Stats!G15-E10 -> 1
A11: =Stats!A16 -> 888 | B11: =Stats!D16 -> Lewis Blackshaw | C11: =Stats!E16 -> Midfield | D11: =SUM(G11,J11,M11) -> 1 | E11: =SUM(H11,K11,N11) -> 0 | F11: =IF(D11>0,E11/D11,"") -> 0 | G11: =COUNTIFS(Stats!$I$4:$CG$4,G$1,Stats!$I16:$CG16,"<>") -> 1 | H11: =SUMIF(Stats!$I$4:$CF$4,G$1,Stats!$J16:$CI16) -> 0 | I11: =IF(G11>0,H11/G11,"") -> 0 | J11: =COUNTIFS(Stats!$I$4:$CG$4,J$1,Stats!$I16:$CG16,"<>") -> 0 | K11: =SUMIF(Stats!$I$4:$CF$4,J$1,Stats!$J16:$CI16) -> 0 | L11: =IF(J11>0,K11/J11,"") | M11: =COUNTIFS(Stats!$I$4:$CG$4,M$1,Stats!$I16:$CG16,"<>") -> 0 | N11: =SUMIF(Stats!$I$4:$CF$4,M$1,Stats!$J16:$CI16) -> 0 | O11: =IF(M11>0,N11/M11,"") | P11: =COUNTIFS(Stats!$L$9:$CG$9,"R",Stats!$L16:$CG16,">0") -> 0 | Q11: =SUMIF(Stats!$L$9:$CG$9,"R",Stats!$L16:$CG16) -> 0 | R11: =Stats!G16-E11 -> 0
A12: =Stats!A17 -> 3 | B12: =Stats!D17 -> Andy Booth | C12: =Stats!E17 -> Defence | D12: =SUM(G12,J12,M12) -> 12 | E12: =SUM(H12,K12,N12) -> 0 | F12: =IF(D12>0,E12/D12,"") -> 0 | G12: =COUNTIFS(Stats!$I$4:$CG$4,G$1,Stats!$I17:$CG17,"<>") -> 12 | H12: =SUMIF(Stats!$I$4:$CF$4,G$1,Stats!$J17:$CI17) -> 0 | I12: =IF(G12>0,H12/G12,"") -> 0 | J12: =COUNTIFS(Stats!$I$4:$CG$4,J$1,Stats!$I17:$CG17,"<>") -> 0 | K12: =SUMIF(Stats!$I$4:$CF$4,J$1,Stats!$J17:$CI17) -> 0 | L12: =IF(J12>0,K12/J12,"") | M12: =COUNTIFS(Stats!$I$4:$CG$4,M$1,Stats!$I17:$CG17,"<>") -> 0 | N12: =SUMIF(Stats!$I$4:$CF$4,M$1,Stats!$J17:$CI17) -> 0 | O12: =IF(M12>0,N12/M12,"") | P12: =COUNTIFS(Stats!$L$9:$CG$9,"R",Stats!$L17:$CG17,">0") -> 2 | Q12: =SUMIF(Stats!$L$9:$CG$9,"R",Stats!$L17:$CG17) -> 8 | R12: =Stats!G17-E12 -> 0
A13: =Stats!A18 -> 888 | B13: =Stats!D18 -> Lygon Bowen-west | C13: =Stats!E18 -> Goal | D13: =SUM(G13,J13,M13) -> 1 | E13: =SUM(H13,K13,N13) -> 0 | F13: =IF(D13>0,E13/D13,"") -> 0 | G13: =COUNTIFS(Stats!$I$4:$CG$4,G$1,Stats!$I18:$CG18,"<>") -> 1 | H13: =SUMIF(Stats!$I$4:$CF$4,G$1,Stats!$J18:$CI18) -> 0 | I13: =IF(G13>0,H13/G13,"") -> 0 | J13: =COUNTIFS(Stats!$I$4:$CG$4,J$1,Stats!$I18:$CG18,"<>") -> 0 | K13: =SUMIF(Stats!$I$4:$CF$4,J$1,Stats!$J18:$CI18) -> 0 | L13: =IF(J13>0,K13/J13,"") | M13: =COUNTIFS(Stats!$I$4:$CG$4,M$1,Stats!$I18:$CG18,"<>") -> 0 | N13: =SUMIF(Stats!$I$4:$CF$4,M$1,Stats!$J18:$CI18) -> 0 | O13: =IF(M13>0,N13/M13,"") | P13: =COUNTIFS(Stats!$L$9:$CG$9,"R",Stats!$L18:$CG18,">0") -> 0 | Q13: =SUMIF(Stats!$L$9:$CG$9,"R",Stats!$L18:$CG18) -> 0 | R13: =Stats!G18-E13 -> 0
A14: =Stats!A19 -> 888 | B14: =Stats!D19 -> Billy Camuso | C14: =Stats!E19 -> Attack | D14: =SUM(G14,J14,M14) -> 9 | E14: =SUM(H14,K14,N14) -> 2 | F14: =IF(D14>0,E14/D14,"") -> 0.22222222 | G14: =COUNTIFS(Stats!$I$4:$CG$4,G$1,Stats!$I19:$CG19,"<>") -> 8 | H14: =SUMIF(Stats!$I$4:$CF$4,G$1,Stats!$J19:$CI19) -> 2 | I14: =IF(G14>0,H14/G14,"") -> 0.25 | J14: =COUNTIFS(Stats!$I$4:$CG$4,J$1,Stats!$I19:$CG19,"<>") -> 1 | K14: =SUMIF(Stats!$I$4:$CF$4,J$1,Stats!$J19:$CI19) -> 0 | L14: =IF(J14>0,K14/J14,"") -> 0 | M14: =COUNTIFS(Stats!$I$4:$CG$4,M$1,Stats!$I19:$CG19,"<>") -> 0 | N14: =SUMIF(Stats!$I$4:$CF$4,M$1,Stats!$J19:$CI19) -> 0 | O14: =IF(M14>0,N14/M14,"") | P14: =COUNTIFS(Stats!$L$9:$CG$9,"R",Stats!$L19:$CG19,">0") -> 0 | Q14: =SUMIF(Stats!$L$9:$CG$9,"R",Stats!$L19:$CG19) -> 0 | R14: =Stats!G19-E14 -> 0
A15: =Stats!A20 -> 6 | B15: =Stats!D20 -> David Copple | C15: =Stats!E20 -> Defence | D15: =SUM(G15,J15,M15) -> 14 | E15: =SUM(H15,K15,N15) -> 0 | F15: =IF(D15>0,E15/D15,"") -> 0 | G15: =COUNTIFS(Stats!$I$4:$CG$4,G$1,Stats!$I20:$CG20,"<>") -> 13 | H15: =SUMIF(Stats!$I$4:$CF$4,G$1,Stats!$J20:$CI20) -> 0 | I15: =IF(G15>0,H15/G15,"") -> 0 | J15: =COUNTIFS(Stats!$I$4:$CG$4,J$1,Stats!$I20:$CG20,"<>") -> 1 | K15: =SUMIF(Stats!$I$4:$CF$4,J$1,Stats!$J20:$CI20) -> 0 | L15: =IF(J15>0,K15/J15,"") -> 0 | M15: =COUNTIFS(Stats!$I$4:$CG$4,M$1,Stats!$I20:$CG20,"<>") -> 0 | N15: =SUMIF(Stats!$I$4:$CF$4,M$1,Stats!$J20:$CI20) -> 0 | O15: =IF(M15>0,N15/M15,"") | P15: =COUNTIFS(Stats!$L$9:$CG$9,"R",Stats!$L20:$CG20,">0") -> 0 | Q15: =SUMIF(Stats!$L$9:$CG$9,"R",Stats!$L20:$CG20) -> 0 | R15: =Stats!G20-E15 -> 0
A16: =Stats!A21 -> 888 | B16: =Stats!D21 -> Eddie Dale | C16: =Stats!E21 -> Midfield/FO | D16: =SUM(G16,J16,M16) -> 6 | E16: =SUM(H16,K16,N16) -> 0 | F16: =IF(D16>0,E16/D16,"") -> 0 | G16: =COUNTIFS(Stats!$I$4:$CG$4,G$1,Stats!$I21:$CG21,"<>") -> 5 | H16: =SUMIF(Stats!$I$4:$CF$4,G$1,Stats!$J21:$CI21) -> 0 | I16: =IF(G16>0,H16/G16,"") -> 0 | J16: =COUNTIFS(Stats!$I$4:$CG$4,J$1,Stats!$I21:$CG21,"<>") -> 1 | K16: =SUMIF(Stats!$I$4:$CF$4,J$1,Stats!$J21:$CI21) -> 0 | L16: =IF(J16>0,K16/J16,"") -> 0 | M16: =COUNTIFS(Stats!$I$4:$CG$4,M$1,Stats!$I21:$CG21,"<>") -> 0 | N16: =SUMIF(Stats!$I$4:$CF$4,M$1,Stats!$J21:$CI21) -> 0 | O16: =IF(M16>0,N16/M16,"") | P16: =COUNTIFS(Stats!$L$9:$CG$9,"R",Stats!$L21:$CG21,">0") -> 0 | Q16: =SUMIF(Stats!$L$9:$CG$9,"R",Stats!$L21:$CG21) -> 0 | R16: =Stats!G21-E16 -> 0
... A44: =Stats!A49 -> 777 | B44: =Stats!D49 -> A.N.Other | C44: =Stats!E49 -> 0 | D44: =SUM(G44,J44,M44) -> 0 | E44: =SUM(H44,K44,N44) -> 0 | F44: =IF(D44>0,E44/D44,"") | G44: =COUNTIFS(Stats!$I$4:$CG$4,G$1,Stats!$I49:$CG49,"<>") -> 0 | H44: =SUMIF(Stats!$I$4:$CF$4,G$1,Stats!$J49:$CI49) -> 0 | I44: =IF(G44>0,H44/G44,"") | J44: =COUNTIFS(Stats!$I$4:$CG$4,J$1,Stats!$I49:$CG49,"<>") -> 0 | K44: =SUMIF(Stats!$I$4:$CF$4,J$1,Stats!$J49:$CI49) -> 0 | L44: =IF(J44>0,K44/J44,"") | M44: =COUNTIFS(Stats!$I$4:$CG$4,M$1,Stats!$I49:$CG49,"<>") -> 0 | N44: =SUMIF(Stats!$I$4:$CF$4,M$1,Stats!$J49:$CI49) -> 0 | O44: =IF(M44>0,N44/M44,"") | P44: =COUNTIFS(Stats!$L$9:$CG$9,"R",Stats!$L49:$CG49,">0") -> 0 | Q44: =SUMIF(Stats!$L$9:$CG$9,"R",Stats!$L49:$CG49) -> 0 | R44: =Stats!G49-E44 -> 0
B46: Total | E46: =SUM(E5:E45) -> 95 | H46: =SUM(H5:H45) -> 92 | K46: =SUM(K5:K45) -> 3
C48: This | D48: =SUM(D4:D45) -> 212 | E48: Diff | G48: =SUM(G5:G45) -> 199 | J48: =SUM(J5:J45) -> 13 | M48: =SUM(M5:M45) -> 0
C49: Sum league/fl | D49: =SUM(G48:M48) -> 212 | E49: =D48-D49 -> 0
C50: Stats | D50: =Stats!F50 -> 212 | E50: =D48-D50 -> 0
A52: 888 | B52: A.N.Other | D52: =SUMIF($A4:$A45,"777",D4:D45)+D54 -> 0 | E52: =SUMIF($A4:$A45,"777",E4:E45) -> 0 | G52: =SUMIF($A4:$A45,"777",G4:G45)+G54 -> 0 | H52: =SUMIF($A4:$A45,"777",H4:H45) -> 0 | J52: =SUMIF($A4:$A45,"777",J4:J45)+J54 -> 0 | K52: =SUMIF($A4:$A45,"777",K4:K45) -> 0 | M52: =SUMIF($A4:$A45,"777",M4:M45)+M54 -> 0 | N52: =SUMIF($A4:$A45,"777",N4:N45) -> 0
C54: fudge | D54: 0
C55: fudge-flags | D55: 0
