Workbook

Sheet Stats
B1: Date | G1: 42259 | K1: 42266 | O1: 42287 | S1: 42294 | W1: 42301 | AA1: 42308 | AE1: 42315 | AI1: 42322 | AM1: 42329 | AQ1: 42336 | AU1: 42343 | AY1: 42350 | BC1: 42378 | BG1: 42385 | BK1: 42392 | BO1: 42406 | BS1: 42413 | BW1: 42420 | CA1: 42441 | CE1: 42448 | CI1: 42462
B2: Team | G2: Croydon | K2: Blues | O2: Cardiff | S2: Hillcroft | W2: Blues | AA2: Hampstead | AE2: Reading | AI2: Spencer | AM2: Spencer | AQ2: Hitchin | AU2: Bristol | AY2: EG | BC2: Cardiff | BG2: Hillcroft | BK2: Blues | BO2: Hampstead | BS2: Reading | BW2: Spencer | CA2: Hitchin | CE2: EG | CI2: Bristol
B3: Venue | F3: Avg | G3: Home | K3: Away | O3: Home | S3: Away | W3: Home | AA3: Home | AE3: Away | AI3: Away | AM3: Home | AQ3: Away | AU3: Away | AY3: Home | BC3: Away | BG3: Home | BK3: Away | BO3: Away | BS3: Home | BW3: Away | CA3: Home | CE3: Away | CI3: Home
B4: Competition | G4: Friendly | K4: Friendly | O4: Prem | S4: Prem | W4: Prem | AA4: Prem | AE4: Prem | AI4: Flags | AM4: Prem | AQ4: Prem | AU4: Prem | AY4: Prem | BC4: Prem | BG4: Prem | BK4: Prem | BO4: Prem | BS4: Prem | BW4: Prem | CA4: Prem | CE4: Prem | CI4: Prem
B5: For | E5: =SUM(G5:CM5) -> 60 | F5: =IF(E7=0,"",E5/E7) -> 3.75 | G5: =SUM(H10:H49) -> 9 | K5: =SUM(L10:L49) -> 4 | O5: =SUM(P10:P49) -> 2 | S5: =SUM(T10:T49) -> 4 | W5: =SUM(X10:X49) -> 0 | AA5: =SUM(AB10:AB49) -> 4 | AE5: =SUM(AF10:AF49) -> 8 | AI5: =SUM(AJ10:AJ49) -> 0 | AM5: =SUM(AN10:AN49) -> 0 | AQ5: =SUM(AR10:AR49) -> 4 | AU5: =SUM(AV10:AV49) -> 5 | AY5: =SUM(AZ10:AZ49) -> 0 | BC5: =SUM(BD10:BD49) -> 0 | BG5: =SUM(BH10:BH49) -> 0 | BK5: =SUM(BL10:BL49) -> 0 | BO5: =SUM(BP10:BP49) -> 1 | BS5: =SUM(BT10:BT49) -> 7 | BW5: =SUM(BX10:BX49) -> 2 | CA5: =SUM(CB10:CB49) -> 3 | CE5: =SUM(CF10:CF49) -> 3 | CI5: =SUM(CJ10:CJ49) -> 4
B6: Against | E6: =SUM(G6:CM6) -> 227 | F6: =IF(E7=0,"",E6/E7) -> 14.1875 | G6: 13 | K6: 9 | O6: 11 | S6: 18 | AA6: 17 | AE6: 16 | AI6: 23 | AQ6: 10 | AU6: 8 | AY6: 17 | BO6: 24 | BS6: 8 | BW6: 24 | CA6: 11 | CE6: 14 | CI6: 4
B7: Played | E7: =COUNT(G6:CM6) -> 16
A8: Columns: Position (GDMA), Goals, Assists, Referee-quarters
A9: No. | B9: Name | C9: Position | D9: Apps | E9: Goals | F9: Assts | G9: P | H9: G | I9: A | J9: R | K9: P | L9: G | M9: A | N9: R | O9: P | P9: G | Q9: A | R9: R | S9: P | T9: G | U9: A | V9: R | W9: P | X9: G | Y9: A | Z9: R | AA9: P | AB9: G | AC9: A | AD9: R | AE9: P | AF9: G | AG9: A | AH9: R | AI9: P | AJ9: G | AK9: A | AL9: R | AM9: P | AN9: G | AO9: A | AP9: R | AQ9: P | AR9: G | AS9: A | AT9: R | AU9: P | AV9: G | AW9: A | AX9: R | AY9: P | AZ9: G | BA9: A | BB9: R | BC9: P | BD9: G | BE9: A | BF9: R | BG9: P | BH9: G | BI9: A | BJ9: R | BK9: P | BL9: G | BM9: A | BN9: R | BO9: P | BP9: G | BQ9: A | BR9: R | BS9: P | BT9: G | BU9: A | BV9: R | BW9: P | BX9: G | BY9: A | BZ9: R | CA9: P | CB9: G | CC9: A | CD9: R | CE9: P | CF9: G | CG9: A | CH9: R | CI9: P | CJ9: G | CK9: A | CL9: R
A10: 17 | B10: Dave Baldwin | C10: Midfield/FO | D10: =COUNTIF(G10:CM10,"=*") -> 8 | E10: =SUMIF(G$9:CM$9,"G",G10:CM10) -> 6 | F10: =SUMIF(G$9:CM$9,"A",G10:CM10) -> 0 | G10: M | H10: 2 | K10: M | L10: 1 | O10: M | S10: M | T10: 1 | AA10: M | AB10: 1 | AE10: M | AF10: 1 | AU10: M | AY10: M
A11: 5 | B11: Justin Baranowski | C11: Attack | D11: =COUNTIF(G11:CM11,"=*") -> 5 | E11: =SUMIF(G$9:CM$9,"G",G11:CM11) -> 3 | F11: =SUMIF(G$9:CM$9,"A",G11:CM11) -> 0 | G11: A | J11: 1 | O11: A | S11: A | T11: 2 | AA11: A | AE11: A | AF11: 1
B12: Sam Baranowski | C12: Midfield | D12: =COUNTIF(G12:CM12,"=*") -> 0 | E12: =SUMIF(G$9:CM$9,"G",G12:CM12) -> 0 | F12: =SUMIF(G$9:CM$9,"A",G12:CM12) -> 0
A13: 2 | B13: Mike Barrett | C13: Midfield/FO | D13: =COUNTIF(G13:CM13,"=*") -> 0 | E13: =SUMIF(G$9:CM$9,"G",G13:CM13) -> 0 | F13: =SUMIF(G$9:CM$9,"A",G13:CM13) -> 0
A14: 3 | B14: Andy Booth | C14: Defence | D14: =COUNTIF(G14:CM14,"=*") -> 9 | E14: =SUMIF(G$9:CM$9,"G",G14:CM14) -> 0 | F14: =SUMIF(G$9:CM$9,"A",G14:CM14) -> 0 | G14: D | K14: A | O14: D | S14: D | AD14: 4 | AI14: A | AQ14: A | AY14: A | CE14: D | CI14: A
D15: =COUNTIF(G15:CM15,"=*") -> 0 | E15: =SUMIF(G$9:CM$9,"G",G15:CM15) -> 0 | F15: =SUMIF(G$9:CM$9,"A",G15:CM15) -> 0
A16: 24 | B16: Felix Bull | C16: Defence | D16: =COUNTIF(G16:CM16,"=*") -> 13 | E16: =SUMIF(G$9:CM$9,"G",G16:CM16) -> 2 | F16: =SUMIF(G$9:CM$9,"A",G16:CM16) -> 0 | G16: D | K16: D | O16: D | S16: D | AA16: D | AI16: D | AQ16: D | AY16: D | BO16: D | BP16: 1 | BS16: D | BW16: D | CA16: D | CB16: 1 | CI16: D
A17: 26 | B17: Rob Clark | C17: Attack | D17: =COUNTIF(G17:CM17,"=*") -> 3 | E17: =SUMIF(G$9:CM$9,"G",G17:CM17) -> 0 | F17: =SUMIF(G$9:CM$9,"A",G17:CM17) -> 0 | O17: M | S17: M | AA17: M
A18: 888 | B18: Ben Colville | C18: Midfield | D18: =COUNTIF(G18:CM18,"=*") -> 1 | E18: =SUMIF(G$9:CM$9,"G",G18:CM18) -> 1 | F18: =SUMIF(G$9:CM$9,"A",G18:CM18) -> 0 | K18: M | L18: 1
A19: 6 | B19: Dave Copple | C19: Defence | D19: =COUNTIF(G19:CM19,"=*") -> 6 | E19: =SUMIF(G$9:CM$9,"G",G19:CM19) -> 0 | F19: =SUMIF(G$9:CM$9,"A",G19:CM19) -> 0 | AI19: D | AU19: D | AY19: D | BO19: D | BS19: D | CI19: D
A20: 11 | B20: Andy Fernando | C20: Midfield/FO | D20: =COUNTIF(G20:CM20,"=*") -> 12 | E20: =SUMIF(G$9:CM$9,"G",G20:CM20) -> 0 | F20: =SUMIF(G$9:CM$9,"A",G20:CM20) -> 0 | G20: M | J20: 1 | K20: M | O20: M | S20: M | AA20: M | AI20: M | AU20: M | AY20: M | BO20: M | CA20: M | CE20: M | CI20: M
A21: 13 | B21: Elliot Fry | C21: Defence | D21: =COUNTIF(G21:CM21,"=*") -> 11 | E21: =SUMIF(G$9:CM$9,"G",G21:CM21) -> 0 | F21: =SUMIF(G$9:CM$9,"A",G21:CM21) -> 0 | O21: D | S21: D | AA21: D | AE21: D | AQ21: D | AU21: D | AY21: D | BO21: D | BS21: D | BW21: D | CI21: D
A22: 888 | B22: Alex Griffiths | C22: Midfield | D22: =COUNTIF(G22:CM22,"=*") -> 12 | E22: =SUMIF(G$9:CM$9,"G",G22:CM22) -> 1 | F22: =SUMIF(G$9:CM$9,"A",G22:CM22) -> 0 | G22: M | O22: M | S22: M | AA22: M | AE22: M | AI22: M | AQ22: M | AR22: 1 | AU22: M | AY22: A | BO22: M | BS22: M | CE22: A
A23: 888 | B23: Jussi Grut | C23: Midfield | D23: =COUNTIF(G23:CM23,"=*") -> 4 | E23: =SUMIF(G$9:CM$9,"G",G23:CM23) -> 0 | F23: =SUMIF(G$9:CM$9,"A",G23:CM23) -> 0 | S23: D | AE23: M | AI23: M | AQ23: A
A24: 21 | B24: Tom Hatton | C24: Midfield | D24: =COUNTIF(G24:CM24,"=*") -> 12 | E24: =SUMIF(G$9:CM$9,"G",G24:CM24) -> 8 | F24: =SUMIF(G$9:CM$9,"A",G24:CM24) -> 4 | G24: M | H24: 5 | K24: M | O24: M | S24: M | AA24: A | AB24: 1 | AE24: A | AI24: A | AU24: A | AV24: 1 | AW24: 4 | BO24: A | BS24: A | BT24: 1 | CA24: A | CE24: A
D25: =COUNTIF(G25:CM25,"=*") -> 0 | E25: =SUMIF(G$9:CM$9,"G",G25:CM25) -> 0 | F25: =SUMIF(G$9:CM$9,"A",G25:CM25) -> 0
A26: 12 | B26: Dave Hudson | C26: LSM/Defence | D26: =COUNTIF(G26:CM26,"=*") -> 0 | E26: =SUMIF(G$9:CM$9,"G",G26:CM26) -> 0 | F26: =SUMIF(G$9:CM$9,"A",G26:CM26) -> 0
A27: 888 | B27: Luke Johnstone | C27: Attack | D27: =COUNTIF(G27:CM27,"=*") -> 0 | E27: =SUMIF(G$9:CM$9,"G",G27:CM27) -> 0 | F27: =SUMIF(G$9:CM$9,"A",G27:CM27) -> 0
A28: 888 | B28: Mylo Johnstone | C28: Attack | D28: =COUNTIF(G28:CM28,"=*") -> 0 | E28: =SUMIF(G$9:CM$9,"G",G28:CM28) -> 0 | F28: =SUMIF(G$9:CM$9,"A",G28:CM28) -> 0
A29: 14 | B29: James Keal | C29: Midfield | D29: =COUNTIF(G29:CM29,"=*") -> 7 | E29: =SUMIF(G$9:CM$9,"G",G29:CM29) -> 2 | F29: =SUMIF(G$9:CM$9,"A",G29:CM29) -> 0 | K29: M | O29: M | S29: M | AE29: M | AF29: 1 | AU29: A | BS29: M | CI29: M | CJ29: 1
A30: 12 | B30: Dara McCreary | C30: Defence | D30: =COUNTIF(G30:CM30,"=*") -> 12 | E30: =SUMIF(G$9:CM$9,"G",G30:CM30) -> 1 | F30: =SUMIF(G$9:CM$9,"A",G30:CM30) -> 0 | K30: D | O30: D | S30: D | AE30: D | AI30: D | AQ30: A | AR30: 1 | AU30: A | BS30: D | BW30: M | CA30: D | CE30: D | CI30: M
A31: 00 | B31: Dan Murphy | C31: Goal | G31: G | K31: G | O31: G | S31: G | AA31: G | AE31: G | AI31: G | AQ31: G
A32: 10 | B32: Darren Novell | C32: Attack | D32: =COUNTIF(G32:CM32,"=*") -> 9 | E32: =SUMIF(G$9:CM$9,"G",G32:CM32) -> 3 | F32: =SUMIF(G$9:CM$9,"A",G32:CM32) -> 0 | G32: A | H32: 1 | O32: A | S32: A | AA32: A | AE32: A | AF32: 1 | AY32: A | BO32: A | BS32: A | BT32: 1 | CI32: A
A33: 7 | B33: Matt Payne | C33: Attack | D33: =COUNTIF(G33:CM33,"=*") -> 5 | E33: =SUMIF(G$9:CM$9,"G",G33:CM33) -> 7 | F33: =SUMIF(G$9:CM$9,"A",G33:CM33) -> 0 | G33: A | O33: A | P33: 2 | S33: A | T33: 1 | AE33: M | AF33: 4 | AI33: A
A34: 15 | B34: Matt Porter | C34: Defence | D34: =COUNTIF(G34:CM34,"=*") -> 4 | E34: =SUMIF(G$9:CM$9,"G",G34:CM34) -> 0 | F34: =SUMIF(G$9:CM$9,"A",G34:CM34) -> 0 | G34: D | O34: D | BW34: D | CA34: D
A35: 888 | B35: Eliot Pugh | C35: Goal | D35: =COUNTIF(G35:CM35,"=*") -> 8 | E35: =SUMIF(G$9:CM$9,"G",G35:CM35) -> 0 | F35: =SUMIF(G$9:CM$9,"A",G35:CM35) -> 0 | AU35: G | AY35: G | BO35: G | BS35: G | BW35: G | CA35: G | CE35: G | CI35: G
A36: 28 | B36: Dave Slaughter | C36: Defence | D36: =COUNTIF(G36:CM36,"=*") -> 12 | E36: =SUMIF(G$9:CM$9,"G",G36:CM36) -> 1 | F36: =SUMIF(G$9:CM$9,"A",G36:CM36) -> 0 | G36: D | J36: 2 | K36: D | R36: 4 | AA36: D | AE36: D | AI36: D | AQ36: D | BB36: 4 | BO36: A | BS36: A | BT36: 1 | BW36: A | CA36: A | CE36: A | CI36: A
A37: 888 | B37: Chase Stuart | C37: Midfield | D37: =COUNTIF(G37:CM37,"=*") -> 1 | E37: =SUMIF(G$9:CM$9,"G",G37:CM37) -> 0 | F37: =SUMIF(G$9:CM$9,"A",G37:CM37) -> 0 | O37: M
A38: 19 | B38: Kaspars 'Stripes' Veips | C38: Defence | D38: =COUNTIF(G38:CM38,"=*") -> 9 | E38: =SUMIF(G$9:CM$9,"G",G38:CM38) -> 8 | F38: =SUMIF(G$9:CM$9,"A",G38:CM38) -> 0 | S38: D | AA38: M | AB38: 2 | AI38: M | AQ38: M | AR38: 2 | AU38: M | AV38: 4 | AY38: M | BO38: M | CA38: M | CE38: M
A39: 4 | B39: Eliot Wilde | C39: Defence | D39: =COUNTIF(G39:CM39,"=*") -> 12 | E39: =SUMIF(G$9:CM$9,"G",G39:CM39) -> 0 | F39: =SUMIF(G$9:CM$9,"A",G39:CM39) -> 0 | G39: D | K39: D | O39: D | AA39: D | AE39: D | AQ39: M | AU39: D | AY39: D | BO39: D | BS39: D | BW39: D | CI39: D
A40: 777 | B40: Hugh Mitchison | BO40: M
...

Sheet Summary
G1: Prem | J1: Flags | M1: Friendly
G2: League | H2: League | I2: League | J2: Flags | K2: Flags | L2: Flags | M2: Friendly | N2: Friendly | O2: Friendly | P2: Referee | Q2: Referee
A3: No. | B3: Name | C3: Position | D3: Apps | E3: Goals | F3: Avg | G3: Apps | H3: Goals | I3: Avg | J3: Apps | K3: Goals | L3: Avg | M3: Apps | N3: Goals | O3: Avg | P3: Games | Q3: Quarters
A5: =Stats!A10 -> 17 | B5: =Stats!B10 -> Dave Baldwin | C5: =Stats!C10 -> Midfield/FO | D5: =SUM(G5,J5,M5) -> 8 | E5: =SUM(H5,K5,N5) -> 6 | F5: =IF(D5>0,E5/D5,"") -> 0.75 | G5: =COUNTIFS(Stats!$G$4:$CM$4,G$1,Stats!$G10:$CM10,"<>") -> 6 | H5: =SUMIF(Stats!$G$4:$CI$4,G$1,Stats!$H10:$CO10) -> 3 | I5: =IF(G5>0,H5/G5,"") -> 0.5 | J5: =COUNTIFS(Stats!$G$4:$CM$4,J$1,Stats!$G10:$CM10,"<>") -> 0 | K5: =SUMIF(Stats!$G$4:$CI$4,J$1,Stats!$H10:$CO10) -> 0 | L5: =IF(J5>0,K5/J5,"") | M5: =COUNTIFS(Stats!$G$4:$CM$4,M$1,Stats!$G10:$CM10,"<>") -> 2 | N5: =SUMIF(Stats!$G$4:$CI$4,M$1,Stats!$H10:$CO10) -> 3 | O5: =IF(M5>0,N5/M5,"") -> 1.5 | P5: =COUNTIFS(Stats!$J$9:$CM$9,"R",Stats!$J10:$CM10,">0") -> 0 | Q5: =SUMIF(Stats!$J$9:$CM$9,"R",Stats!$J10:$CM10) -> 0 | R5: =Stats!E10-E5 -> 0
A6: =Stats!A11 -> 5 | B6: =Stats!B11 -> Justin Baranowski | C6: =Stats!C11 -> Attack | D6: =SUM(G6,J6,M6) -> 5 | E6: =SUM(H6,K6,N6) -> 3 | F6: =IF(D6>0,E6/D6,"") -> 0.6 | G6: =COUNTIFS(Stats!$G$4:$CM$4,G$1,Stats!$G11:$CM11,"<>") -> 4 | H6: =SUMIF(Stats!$G$4:$CI$4,G$1,Stats!$H11:$CO11) -> 3 | I6: =IF(G6>0,H6/G6,"") -> 0.75 | J6: =COUNTIFS(Stats!$G$4:$CM$4,J$1,Stats!$G11:$CM11,"<>") -> 0 | K6: =SUMIF(Stats!$G$4:$CI$4,J$1,Stats!$H11:$CO11) -> 0 | L6: =IF(J6>0,K6/J6,"") | M6: =COUNTIFS(Stats!$G$4:$CM$4,M$1,Stats!$G11:$CM11,"<>") -> 1 | N6: =SUMIF(Stats!$G$4:$CI$4,M$1,Stats!$H11:$CO11) -> 0 | O6: =IF(M6>0,N6/M6,"") -> 0 | P6: =COUNTIFS(Stats!$J$9:$CM$9,"R",Stats!$J11:$CM11,">0") -> 1 | Q6: =SUMIF(Stats!$J$9:$CM$9,"R",Stats!$J11:$CM11) -> 1 | R6: =Stats!E11-E6 -> 0
A7: =Stats!A12 -> 0 | B7: =Stats!B12 -> Sam Baranowski | C7: =Stats!C12 -> Midfield | D7: =SUM(G7,J7,M7) -> 0 | E7: =SUM(H7,K7,N7) -> 0 | F7: =IF(D7>0,E7/D7,"") | G7: =COUNTIFS(Stats!$G$4:$CM$4,G$1,Stats!$G12:$CM12,"<>") -> 0 | H7: =SUMIF(Stats!$G$4:$CI$4,G$1,Stats!$H12:$CO12) -> 0 | I7: =IF(G7>0,H7/G7,"") | J7: =COUNTIFS(Stats!$G$4:$CM$4,J$1,Stats!$G12:$CM12,"<>") -> 0 | K7: =SUMIF(Stats!$G$4:$CI$4,J$1,Stats!$H12:$CO12) -> 0 | L7: =IF(J7>0,K7/J7,"") | M7: =COUNTIFS(Stats!$G$4:$CM$4,M$1,Stats!$G12:$CM12,"<>") -> 0 | N7: =SUMIF(Stats!$G$4:$CI$4,M$1,Stats!$H12:$CO12) -> 0 | O7: =IF(M7>0,N7/M7,"") | P7: =COUNTIFS(Stats!$J$9:$CM$9,"R",Stats!$J12:$CM12,">0") -> 0 | Q7: =SUMIF(Stats!$J$9:$CM$9,"R",Stats!$J12:$CM12) -> 0 | R7: =Stats!E12-E7 -> 0
A8: =Stats!A13 -> 2 | B8: =Stats!B13 -> Mike Barrett | C8: =Stats!C13 -> Midfield/FO | D8: =SUM(G8,J8,M8) -> 0 | E8: =SUM(H8,K8,N8) -> 0 | F8: =IF(D8>0,E8/D8,"") | G8: =COUNTIFS(Stats!$G$4:$CM$4,G$1,Stats!$G13:$CM13,"<>") -> 0 | H8: =SUMIF(Stats!$G$4:$CI$4,G$1,Stats!$H13:$CO13) -> 0 | I8: =IF(G8>0,H8/G8,"") | J8: =COUNTIFS(Stats!$G$4:$CM$4,J$1,Stats!$G13:$CM13,"<>") -> 0 | K8: =SUMIF(Stats!$G$4:$CI$4,J$1,Stats!$H13:$CO13) -> 0 | L8: =IF(J8>0,K8/J8,"") | M8: =COUNTIFS(Stats!$G$4:$CM$4,M$1,Stats!$G13:$CM13,"<>") -> 0 | N8: =SUMIF(Stats!$G$4:$CI$4,M$1,Stats!$H13:$CO13) -> 0 | O8: =IF(M8>0,N8/M8,"") | P8: =COUNTIFS(Stats!$J$9:$CM$9,"R",Stats!$J13:$CM13,">0") -> 0 | Q8: =SUMIF(Stats!$J$9:$CM$9,"R",Stats!$J13:$CM13) -> 0 | R8: =Stats!E13-E8 -> 0
A9: =Stats!A14 -> 3 | B9: =Stats!B14 -> Andy Booth | C9: =Stats!C14 -> Defence | D9: =SUM(G9,J9,M9) -> 9 | E9: =SUM(H9,K9,N9) -> 0 | F9: =IF(D9>0,E9/D9,"") -> 0 | G9: =COUNTIFS(Stats!$G$4:$CM$4,G$1,Stats!$G14:$CM14,"<>") -> 6 | H9: =SUMIF(Stats!$G$4:$CI$4,G$1,Stats!$H14:$CO14) -> 0 | I9: =IF(G9>0,H9/G9,"") -> 0 | J9: =COUNTIFS(Stats!$G$4:$CM$4,J$1,Stats!$G14:$CM14,"<>") -> 1 | K9: =SUMIF(Stats!$G$4:$CI$4,J$1,Stats!$H14:$CO14) -> 0 | L9: =IF(J9>0,K9/J9,"") -> 0 | M9: =COUNTIFS(Stats!$G$4:$CM$4,M$1,Stats!$G14:$CM14,"<>") -> 2 | N9: =SUMIF(Stats!$G$4:$CI$4,M$1,Stats!$H14:$CO14) -> 0 | O9: =IF(M9>0,N9/M9,"") -> 0 | P9: =COUNTIFS(Stats!$J$9:$CM$9,"R",Stats!$J14:$CM14,">0") -> 1 | Q9: =SUMIF(Stats!$J$9:$CM$9,"R",Stats!$J14:$CM14) -> 4 | R9: =Stats!E14-E9 -> 0
A10: =Stats!A15 -> 0 | B10: =Stats!B15 -> 0 | C10: =Stats!C15 -> 0 | D10: =SUM(G10,J10,M10) -> 0 | E10: =SUM(H10,K10,N10) -> 0 | F10: =IF(D10>0,E10/D10,"") | G10: =COUNTIFS(Stats!$G$4:$CM$4,G$1,Stats!$G15:$CM15,"<>") -> 0 | H10: =SUMIF(Stats!$G$4:$CI$4,G$1,Stats!$H15:$CO15) -> 0 | I10: =IF(G10>0,H10/G10,"") | J10: =COUNTIFS(Stats!$G$4:$CM$4,J$1,Stats!$G15:$CM15,"<>") -> 0 | K10: =SUMIF(Stats!$G$4:$CI$4,J$1,Stats!$H15:$CO15) -> 0 | L10: =IF(J10>0,K10/J10,"") | M10: =COUNTIFS(Stats!$G$4:$CM$4,M$1,Stats!$G15:$CM15,"<>") -> 0 | N10: =SUMIF(Stats!$G$4:$CI$4,M$1,Stats!$H15:$CO15) -> 0 | O10: =IF(M10>0,N10/M10,"") | P10: =COUNTIFS(Stats!$J$9:$CM$9,"R",Stats!$J15:$CM15,">0") -> 0 | Q10: =SUMIF(Stats!$J$9:$CM$9,"R",Stats!$J15:$CM15) -> 0 | R10: =Stats!E15-E10 -> 0
A11: =Stats!A16 -> 24 | B11: =Stats!B16 -> Felix Bull | C11: =Stats!C16 -> Defence | D11: =SUM(G11,J11,M11) -> 13 | E11: =SUM(H11,K11,N11) -> 2 | F11: =IF(D11>0,E11/D11,"") -> 0.15384615 | G11: =COUNTIFS(Stats!$G$4:$CM$4,G$1,Stats!$G16:$CM16,"<>") -> 10 | H11: =SUMIF(Stats!$G$4:$CI$4,G$1,Stats!$H16:$CO16) -> 2 | I11: =IF(G11>0,H11/G11,"") -> 0.2 | J11: =COUNTIFS(Stats!$G$4:$CM$4,J$1,Stats!$G16:$CM16,"<>") -> 1 | K11: =SUMIF(Stats!$G$4:$CI$4,J$1,Stats!$H16:$CO16) -> 0 | L11: =IF(J11>0,K11/J11,"") -> 0 | M11: =COUNTIFS(Stats!$G$4:$CM$4,M$1,Stats!$G16:$CM16,"<>") -> 2 | N11: =SUMIF(Stats!$G$4:$CI$4,M$1,Stats!$H16:$CO16) -> 0 | O11: =IF(M11>0,N11/M11,"") -> 0 | P11: =COUNTIFS(Stats!$J$9:$CM$9,"R",Stats!$J16:$CM16,">0") -> 0 | Q11: =SUMIF(Stats!$J$9:$CM$9,"R",Stats!$J16:$CM16) -> 0 | R11: =Stats!E16-E11 -> 0
A12: =Stats!A17 -> 26 | B12: =Stats!B17 -> Rob Clark | C12: =Stats!C17 -> Attack | D12: =SUM(G12,J12,M12) -> 3 | E12: =SUM(H12,K12,N12) -> 0 | F12: =IF(D12>0,E12/D12,"") -> 0 | G12: =COUNTIFS(Stats!$G$4:$CM$4,G$1,Stats!$G17:$CM17,"<>") -> 3 | H12: =SUMIF(Stats!$G$4:$CI$4,G$1,Stats!$H17:$CO17) -> 0 | I12: =IF(G12>0,H12/G12,"") -> 0 | J12: =COUNTIFS(Stats!$G$4:$CM$4,J$1,Stats!$G17:$CM17,"<>") -> 0 | K12: =SUMIF(Stats!$G$4:$CI$4,J$1,Stats!$H17:$CO17) -> 0 | L12: =IF(J12>0,K12/J12,"") | M12: =COUNTIFS(Stats!$G$4:$CM$4,M$1,Stats!$G17:$CM17,"<>") -> 0 | N12: =SUMIF(Stats!$G$4:$CI$4,M$1,Stats!$H17:$CO17) -> 0 | O12: =IF(M12>0,N12/M12,"") | P12: =COUNTIFS(Stats!$J$9:$CM$9,"R",Stats!$J17:$CM17,">0") -> 0 | Q12: =SUMIF(Stats!$J$9:$CM$9,"R",Stats!$J17:$CM17) -> 0 | R12: =Stats!E17-E12 -> 0
A13: =Stats!A18 -> 888 | B13: =Stats!B18 -> Ben Colville | C13: =Stats!C18 -> Midfield | D13: =SUM(G13,J13,M13) -> 1 | E13: =SUM(H13,K13,N13) -> 1 | F13: =IF(D13>0,E13/D13,"") -> 1 | G13: =COUNTIFS(Stats!$G$4:$CM$4,G$1,Stats!$G18:$CM18,"<>") -> 0 | H13: =SUMIF(Stats!$G$4:$CI$4,G$1,Stats!$H18:$CO18) -> 0 | I13: =IF(G13>0,H13/G13,"") | J13: =COUNTIFS(Stats!$G$4:$CM$4,J$1,Stats!$G18:$CM18,"<>") -> 0 | K13: =SUMIF(Stats!$G$4:$CI$4,J$1,Stats!$H18:$CO18) -> 0 | L13: =IF(J13>0,K13/J13,"") | M13: =COUNTIFS(Stats!$G$4:$CM$4,M$1,Stats!$G18:$CM18,"<>") -> 1 | N13: =SUMIF(Stats!$G$4:$CI$4,M$1,Stats!$H18:$CO18) -> 1 | O13: =IF(M13>0,N13/M13,"") -> 1 | P13: =COUNTIFS(Stats!$J$9:$CM$9,"R",Stats!$J18:$CM18,">0") -> 0 | Q13: =SUMIF(Stats!$J$9:$CM$9,"R",Stats!$J18:$CM18) -> 0 | R13: =Stats!E18-E13 -> 0
A14: =Stats!A19 -> 6 | B14: =Stats!B19 -> Dave Copple | C14: =Stats!C19 -> Defence | D14: =SUM(G14,J14,M14) -> 6 | E14: =SUM(H14,K14,N14) -> 0 | F14: =IF(D14>0,E14/D14,"") -> 0 | G14: =COUNTIFS(Stats!$G$4:$CM$4,G$1,Stats!$G19:$CM19,"<>") -> 5 | H14: =SUMIF(Stats!$G$4:$CI$4,G$1,Stats!$H19:$CO19) -> 0 | I14: =IF(G14>0,H14/G14,"") -> 0 | J14: =COUNTIFS(Stats!$G$4:$CM$4,J$1,Stats!$G19:$CM19,"<>") -> 1 | K14: =SUMIF(Stats!$G$4:$CI$4,J$1,Stats!$H19:$CO19) -> 0 | L14: =IF(J14>0,K14/J14,"") -> 0 | M14: =COUNTIFS(Stats!$G$4:$CM$4,M$1,Stats!$G19:$CM19,"<>") -> 0 | N14: =SUMIF(Stats!$G$4:$CI$4,M$1,Stats!$H19:$CO19) -> 0 | O14: =IF(M14>0,N14/M14,"") | P14: =COUNTIFS(Stats!$J$9:$CM$9,"R",Stats!$J19:$CM19,">0") -> 0 | Q14: =SUMIF(Stats!$J$9:$CM$9,"R",Stats!$J19:$CM19) -> 0 | R14: =Stats!E19-E14 -> 0
A15: =Stats!A20 -> 11 | B15: =Stats!B20 -> Andy Fernando | C15: =Stats!C20 -> Midfield/FO | D15: =SUM(G15,J15,M15) -> 12 | E15: =SUM(H15,K15,N15) -> 0 | F15: =IF(D15>0,E15/D15,"") -> 0 | G15: =COUNTIFS(Stats!$G$4:$CM$4,G$1,Stats!$G20:$CM20,"<>") -> 9 | H15: =SUMIF(Stats!$G$4:$CI$4,G$1,Stats!$H20:$CO20) -> 0 | I15: =IF(G15>0,H15/G15,"") -> 0 | J15: =COUNTIFS(Stats!$G$4:$CM$4,J$1,Stats!$G20:$CM20,"<>") -> 1 | K15: =SUMIF(Stats!$G$4:$CI$4,J$1,Stats!$H20:$CO20) -> 0 | L15: =IF(J15>0,K15/J15,"") -> 0 | M15: =COUNTIFS(Stats!$G$4:$CM$4,M$1,Stats!$G20:$CM20,"<>") -> 2 | N15: =SUMIF(Stats!$G$4:$CI$4,M$1,Stats!$H20:$CO20) -> 0 | O15: =IF(M15>0,N15/M15,"") -> 0 | P15: =COUNTIFS(Stats!$J$9:$CM$9,"R",Stats!$J20:$CM20,">0") -> 1 | Q15: =SUMIF(Stats!$J$9:$CM$9,"R",Stats!$J20:$CM20) -> 1 | R15: =Stats!E20-E15 -> 0
A16: =Stats!A21 -> 13 | B16: =Stats!B21 -> Elliot Fry | C16: =Stats!C21 -> Defence | D16: =SUM(G16,J16,M16) -> 11 | E16: =SUM(H16,K16,N16) -> 0 | F16: =IF(D16>0,E16/D16,"") -> 0 | G16: =COUNTIFS(Stats!$G$4:$CM$4,G$1,Stats!$G21:$CM21,"<>") -> 11 | H16: =SUMIF(Stats!$G$4:$CI$4,G$1,Stats!$H21:$CO21) -> 0 | I16: =IF(G16>0,H16/G16,"") -> 0 | J16: =COUNTIFS(Stats!$G$4:$CM$4,J$1,Stats!$G21:$CM21,"<>") -> 0 | K16: =SUMIF(Stats!$G$4:$CI$4,J$1,Stats!$H21:$CO21) -> 0 | L16: =IF(J16>0,K16/J16,"") | M16: =COUNTIFS(Stats!$G$4:$CM$4,M$1,Stats!$G21:$CM21,"<>") -> 0 | N16: =SUMIF(Stats!$G$4:$CI$4,M$1,Stats!$H21:$CO21) -> 0 | O16: =IF(M16>0,N16/M16,"") | P16: =COUNTIFS(Stats!$J$9:$CM$9,"R",Stats!$J21:$CM21,">0") -> 0 | Q16: =SUMIF(Stats!$J$9:$CM$9,"R",Stats!$J21:$CM21) -> 0 | R16: =Stats!E21-E16 -> 0
... A44: =Stats!A49 -> 777 | B44: =Stats!B49 -> A.N.Other | C44: =Stats!C49 -> 0 | D44: =SUM(G44,J44,M44) -> 1 | E44: =SUM(H44,K44,N44) -> 1 | F44: =IF(D44>0,E44/D44,"") -> 1 | G44: =COUNTIFS(Stats!$G$4:$CM$4,G$1,Stats!$G49:$CM49,"<>") -> 0 | H44: =SUMIF(Stats!$G$4:$CI$4,G$1,Stats!$H49:$CO49) -> 0 | I44: =IF(G44>0,H44/G44,"") | J44: =COUNTIFS(Stats!$G$4:$CM$4,J$1,Stats!$G49:$CM49,"<>") -> 0 | K44: =SUMIF(Stats!$G$4:$CI$4,J$1,Stats!$H49:$CO49) -> 0 | L44: =IF(J44>0,K44/J44,"") | M44: =COUNTIFS(Stats!$G$4:$CM$4,M$1,Stats!$G49:$CM49,"<>") -> 1 | N44: =SUMIF(Stats!$G$4:$CI$4,M$1,Stats!$H49:$CO49) -> 1 | O44: =IF(M44>0,N44/M44,"") -> 1 | P44: =COUNTIFS(Stats!$J$9:$CM$9,"R",Stats!$J49:$CM49,">0") -> 0 | Q44: =SUMIF(Stats!$J$9:$CM$9,"R",Stats!$J49:$CM49) -> 0 | R44: =Stats!E49-E44 -> 0
B46: Total | E46: =SUM(E5:E45) -> 60 | H46: =SUM(H5:H45) -> 47 | K46: =SUM(K5:K45) -> 0
C48: This | D48: =SUM(D4:D45) -> 193 | E48: Diff | G48: =SUM(G5:G45) -> 156 | J48: =SUM(J5:J45) -> 12 | M48: =SUM(M5:M45) -> 25
C49: Sum league/fl | D49: =SUM(G48:M48) -> 193 | E49: =D48-D49 -> 0
C50: Stats | D50: =Stats!D50 -> 184 | E50: =D48-D50 -> 9
A52: 888 | B52: A.N.Other | D52: =SUMIF($A4:$A45,"777",D4:D45)+D54 -> 2 | E52: =SUMIF($A4:$A45,"777",E4:E45) -> 1 | G52: =SUMIF($A4:$A45,"777",G4:G45)+G54 -> 1 | H52: =SUMIF($A4:$A45,"777",H4:H45) -> 0 | J52: =SUMIF($A4:$A45,"777",J4:J45)+J54 -> 0 | K52: =SUMIF($A4:$A45,"777",K4:K45) -> 0 | M52: =SUMIF($A4:$A45,"777",M4:M45)+M54 -> 1 | N52: =SUMIF($A4:$A45,"777",N4:N45) -> 1
C54: fudge | D54: 0
C55: fudge-flags | D55: 0
